[2021-05-12 10:28:03,490] {taskinstance.py:877} INFO - Dependencies all met for <TaskInstance: status_test.task3 2021-05-11T00:00:00+00:00 [queued]>
[2021-05-12 10:28:03,497] {taskinstance.py:877} INFO - Dependencies all met for <TaskInstance: status_test.task3 2021-05-11T00:00:00+00:00 [queued]>
[2021-05-12 10:28:03,498] {taskinstance.py:1068} INFO - 
--------------------------------------------------------------------------------
[2021-05-12 10:28:03,498] {taskinstance.py:1069} INFO - Starting attempt 1 of 2
[2021-05-12 10:28:03,498] {taskinstance.py:1070} INFO - 
--------------------------------------------------------------------------------
[2021-05-12 10:28:03,639] {taskinstance.py:1089} INFO - Executing <Task(BashOperator): task3> on 2021-05-11T00:00:00+00:00
[2021-05-12 10:28:03,642] {standard_task_runner.py:52} INFO - Started process 2173215 to run task
[2021-05-12 10:28:03,647] {standard_task_runner.py:76} INFO - Running: ['airflow', 'tasks', 'run', 'status_test', 'task3', '2021-05-11T00:00:00+00:00', '--job-id', '50', '--pool', 'default_pool', '--raw', '--subdir', 'DAGS_FOLDER/task_status.py', '--cfg-path', '/tmp/tmp6ndiah1p', '--error-file', '/tmp/tmpre21w5ot']
[2021-05-12 10:28:03,648] {standard_task_runner.py:77} INFO - Job 50: Subtask task3
[2021-05-12 10:28:03,820] {logging_mixin.py:104} INFO - Running <TaskInstance: status_test.task3 2021-05-11T00:00:00+00:00 [running]> on host sdn-k8s-b2-3-3.maas
[2021-05-12 10:28:04,226] {taskinstance.py:1281} INFO - Exporting the following env vars:
AIRFLOW_CTX_DAG_EMAIL=davidwu5858@gmail.com
AIRFLOW_CTX_DAG_OWNER=airflow
AIRFLOW_CTX_DAG_ID=status_test
AIRFLOW_CTX_TASK_ID=task3
AIRFLOW_CTX_EXECUTION_DATE=2021-05-11T00:00:00+00:00
AIRFLOW_CTX_DAG_RUN_ID=scheduled__2021-05-11T00:00:00+00:00
[2021-05-12 10:28:04,226] {bash.py:135} INFO - Tmp dir root location: 
 /tmp
[2021-05-12 10:28:04,227] {bash.py:158} INFO - Running command: echo"im task 3!!!!!!!!!!!!!!!!!!!!!!" && exit 0 || exit 1
[2021-05-12 10:28:04,235] {bash.py:169} INFO - Output:
[2021-05-12 10:28:04,236] {bash.py:173} INFO - bash: echoim task 3!!!!!!!!!!!!!!!!!!!!!!: command not found
[2021-05-12 10:28:04,237] {bash.py:177} INFO - Command exited with return code 1
[2021-05-12 10:28:04,244] {taskinstance.py:1482} ERROR - Task failed with exception
Traceback (most recent call last):
  File "/home/ubuntu/venv/lib/python3.8/site-packages/airflow/models/taskinstance.py", line 1138, in _run_raw_task
    self._prepare_and_execute_task_with_callbacks(context, task)
  File "/home/ubuntu/venv/lib/python3.8/site-packages/airflow/models/taskinstance.py", line 1311, in _prepare_and_execute_task_with_callbacks
    result = self._execute_task(context, task_copy)
  File "/home/ubuntu/venv/lib/python3.8/site-packages/airflow/models/taskinstance.py", line 1341, in _execute_task
    result = task_copy.execute(context=context)
  File "/home/ubuntu/venv/lib/python3.8/site-packages/airflow/operators/bash.py", line 180, in execute
    raise AirflowException('Bash command failed. The command returned a non-zero exit code.')
airflow.exceptions.AirflowException: Bash command failed. The command returned a non-zero exit code.
[2021-05-12 10:28:04,246] {taskinstance.py:1525} INFO - Marking task as UP_FOR_RETRY. dag_id=status_test, task_id=task3, execution_date=20210511T000000, start_date=20210512T102803, end_date=20210512T102804
[2021-05-12 10:28:04,420] {local_task_job.py:146} INFO - Task exited with return code 1
